Workbook

Sheet Sheet1
A2: Nome do Projeto: CTHFeedTactics | B2: CTHFeedTactics
A3: Équipe: CHTFeedTactics | B3: Leonardo Oliveira / 2523546; Lucas Silva / 2422728; João Gabriel de Holanda / 2522687
A5: Histórias | B5: Valor de Negócio | C5: Risco | D5: Quadrante | E5: Prioridade | F5: Release | G5: Pontuação | H5: Iteração
A6: Jornada 1.2 — Enzo: pesquisar IOC com contexto setorial e filtros | B6: A | C6: A | D6: =IF(B6="A", IF(C6="A", 4, 3), IF(C6="A", 1, 2)) -> 4 | E6: 1 | F6: 1 | G6: 8 | H6: 1
A7: Jornada 1.3 — Enzo: consultar a reputação do IOC em feeds reputacionais | B7: A | C7: A | D7: =IF(B7="A", IF(C7="A", 4, 3), IF(C7="A", 1, 2)) -> 4 | E7: 2 | F7: 1 | G7: 8 | H7: 1
A8: Jornada 2.2 — Paulo: consumir IOCs via API com filtros setoriais | B8: A | C8: A | D8: =IF(B8="A", IF(C8="A", 4, 3), IF(C8="A", 1, 2)) -> 4 | E8: 3 | F8: 3 | G8: 8 | H8: 4
A9: Jornada 2.3 — Paulo: ingerir inteligência em STIX/TAXII no pipeline interno | B9: A | C9: A | D9: =IF(B9="A", IF(C9="A", 4, 3), IF(C9="A", 1, 2)) -> 4 | E9: 4 | F9: 3 | G9: 8 | H9: 4
A10: Jornada 3 — Edgar: acompanhamento setorial e compartilhamento controlado | B10: A | C10: A | D10: =IF(B10="A", IF(C10="A", 4, 3), IF(C10="A", 1, 2)) -> 4 | E10: 5 | F10: 2 | G10: 8 | H10: 3
A11: Jornada 7 — Marina: pesquisar e correlacionar um IOC | B11: A | C11: A | D11: =IF(B11="A", IF(C11="A", 4, 3), IF(C11="A", 1, 2)) -> 4 | E11: 6 | F11: 1 | G11: 3 | H11: 2
A12: Jornada 12 — Edgar: solicitar verificação da conta | B12: A | C12: A | D12: =IF(B12="A", IF(C12="A", 4, 3), IF(C12="A", 1, 2)) -> 4 | E12: 7 | F12: 1 | G12: 8 | H12: 2
A13: Jornada 13 — Marina: controlar privacidade das informações profissionais | B13: A | C13: A | D13: =IF(B13="A", IF(C13="A", 4, 3), IF(C13="A", 1, 2)) -> 4 | E13: 8 | F13: 2 | G13: 3 | H13: 3
A14: Jornada 14 — Edgar: publicar inteligência com classificação de compartilhamento | B14: A | C14: A | D14: =IF(B14="A", IF(C14="A", 4, 3), IF(C14="A", 1, 2)) -> 4 | E14: 9 | F14: 2 | G14: 8 | H14: 3
A15: Jornada 15 — Paulo: exportar inteligência para ferramentas externas | B15: A | C15: A | D15: =IF(B15="A", IF(C15="A", 4, 3), IF(C15="A", 1, 2)) -> 4 | E15: 10 | F15: 3 | G15: 5 | H15: 5
A16: Jornada 19 — Paulo: contribuir com novos IOCs para publicação existente | B16: A | C16: A | D16: =IF(B16="A", IF(C16="A", 4, 3), IF(C16="A", 1, 2)) -> 4 | E16: 11 | F16: 3 | G16: 8 | H16: 4
A17: Jornada 20 — Marina: reportar informação incorreta ou suspeita | B17: A | C17: A | D17: =IF(B17="A", IF(C17="A", 4, 3), IF(C17="A", 1, 2)) -> 4 | E17: 12 | F17: 2 | G17: 5 | H17: 3
... A29: Jornada 17 — Marina: acompanhar novas informações de ameaça investigada | B29: B | C29: B | D29: =IF(B29="A", IF(C29="A", 4, 3), IF(C29="A", 1, 2)) -> 2 | E29: 24 | F29: 3 | G29: 5 | H29: 5

Sheet Planning Poker
A1: Planning Poker — CTHFeedTactics
A2: Escala Fibonacci: 1, 2, 3, 5, 8, 13, 21. Quanto maior a pontuação, mais complexa a história. História acima de 13 pontos é quebrada em funcionalidades menores antes de entrar em uma iteração.
A3: História de referência: Jornada 11 (salvar ameaça) = 2 pontos. As demais foram estimadas por comparação com ela e entre si, dentro de cada release.
A4: Funcionalidades repetidas entre jornadas (cadastro, feed, busca, reputação, conversor STIX) foram pontuadas uma vez só, na história que as constrói primeiro. As histórias seguintes contam apenas o que falta construir.
A5: Pontuação anterior = valores da versão anterior desta planilha. As pontuações da aba Sheet1 são a fonte; as colunas com fórmula nesta aba buscam os valores de lá.
A6: Capacidade assumida por iteração (pontos): | D6: 30 | E6: Premissa da equipe. Ajustar depois de medir a velocidade real da iteração 1.
A8: 1. Estimativa por release (comparação entre as histórias)
A9: Release | B9: História | C9: Pontuação anterior | D9: Planning Poker | E9: Comparação com outras histórias | F9: Decisão
A10: 1 | B10: Jornada 1 — Enzo: cadastro, consulta e triagem contextualizada de alerta | C10: 5 | D10: 21 | E10: Junta feed, busca com filtros e consulta a feed reputacional externo. Equivale à J6 + J12 + J8 somadas. | F10: =IF(D10>13,"Quebrar (ver item 2)",IF(D10=13,"Manter (no limite)","Manter")) -> Quebrar (ver item 2)
A11: 1 | B11: Jornada 6 — Rafael: configurar perfil e personalizar feed por indústria | C11: 3 | D11: =INDEX(Sheet1!$G$6:$G$29,MATCH($B11,Sheet1!$A$6:$A$29,0)) -> 8 | E11: Cadastro com confirmação de e-mail, login e perfil com indústria. Inclui o passo 1 da J1, por isso foi pontuado só aqui. | F11: =IF(D11>13,"Quebrar (ver item 2)",IF(D11=13,"Manter (no limite)","Manter")) -> Manter
A12: 1 | B12: Jornada 12 — Edgar: solicitar verificação da conta | C12: 5 | D12: =INDEX(Sheet1!$G$6:$G$29,MATCH($B12,Sheet1!$A$6:$A$29,0)) -> 8 | E12: Mesmo porte da J6: formulário, acompanhamento do status e a análise da solicitação do lado administrativo, que a jornada não mostra. | F12: =IF(D12>13,"Quebrar (ver item 2)",IF(D12=13,"Manter (no limite)","Manter")) -> Manter
A13: 1 | B13: Jornada 8 — Enzo: entender uma TTP observada em um alerta | C13: 3 | D13: =INDEX(Sheet1!$G$6:$G$29,MATCH($B13,Sheet1!$A$6:$A$29,0)) -> 5 | E13: Página nova de TTP e carga do catálogo MITRE ATT&CK. Maior que J7 e J9, menor que J6. | F13: =IF(D13>13,"Quebrar (ver item 2)",IF(D13=13,"Manter (no limite)","Manter")) -> Manter
A14: 1 | B14: Jornada 7 — Marina: pesquisar e correlacionar um IOC | C14: 5 | D14: =INDEX(Sheet1!$G$6:$G$29,MATCH($B14,Sheet1!$A$6:$A$29,0)) -> 3 | E14: Busca e reputação já vêm da J1; sobra relacionar o IOC a campanhas, ofensores e publicações anteriores. | F14: =IF(D14>13,"Quebrar (ver item 2)",IF(D14=13,"Manter (no limite)","Manter")) -> Manter
A15: 1 | B15: Jornada 9 — Paulo: analisar um ofensor ativo contra sua indústria | C15: 3 | D15: =INDEX(Sheet1!$G$6:$G$29,MATCH($B15,Sheet1!$A$6:$A$29,0)) -> 3 | E15: Mesmo padrão de página da J8, aplicado ao ofensor. | F15: =IF(D15>13,"Quebrar (ver item 2)",IF(D15=13,"Manter (no limite)","Manter")) -> Manter
A16: 1 | B16: Jornada 16 — Enzo: filtrar o feed para encontrar ameaças recentes | C16: 3 | D16: =INDEX(Sheet1!$G$6:$G$29,MATCH($B16,Sheet1!$A$6:$A$29,0)) -> 3 | E16: Reaproveita os filtros da J1.2, agora aplicados ao feed. | F16: =IF(D16>13,"Quebrar (ver item 2)",IF(D16=13,"Manter (no limite)","Manter")) -> Manter
A17: 1 | B17: Jornada 4 — Rafael: monitoramento diário de ameaças relevantes | C17: 5 | D17: =INDEX(Sheet1!$G$6:$G$29,MATCH($B17,Sheet1!$A$6:$A$29,0)) -> 2 | E17: Feed e detalhes já existem na J1; sobra copiar e compartilhar o link. Mesmo porte da J11 (referência). | F17: =IF(D17>13,"Quebrar (ver item 2)",IF(D17=13,"Manter (no limite)","Manter")) -> Manter
A18: 2 | B18: Jornada 3 — Edgar: acompanhamento setorial e compartilhamento controlado | C18: 8 | D18: =INDEX(Sheet1!$G$6:$G$29,MATCH($B18,Sheet1!$A$6:$A$29,0)) -> 8 | E18: Formulário de publicação e pré-validação dos IOCs, reaproveitando a consulta reputacional da J1.3. | F18: =IF(D18>13,"Quebrar (ver item 2)",IF(D18=13,"Manter (no limite)","Manter")) -> Manter
A19: 2 | B19: Jornada 14 — Edgar: publicar inteligência com classificação de compartilhamento | C19: 5 | D19: =INDEX(Sheet1!$G$6:$G$29,MATCH($B19,Sheet1!$A$6:$A$29,0)) -> 8 | E19: Mesmo porte da J3: escolha do TLP e aplicação das regras de visibilidade no feed, na busca e nos detalhes. | F19: =IF(D19>13,"Quebrar (ver item 2)",IF(D19=13,"Manter (no limite)","Manter")) -> Manter
A20: 2 | B20: Jornada 10 — Rafael: receber alerta sobre nova ameaça setorial | C20: 5 | D20: =INDEX(Sheet1!$G$6:$G$29,MATCH($B20,Sheet1!$A$6:$A$29,0)) -> 5 | E20: Preferências de notificação, disparo por indústria e envio de e-mail (o envio já existe desde a J6). | F20: =IF(D20>13,"Quebrar (ver item 2)",IF(D20=13,"Manter (no limite)","Manter")) -> Manter
A21: 2 | B21: Jornada 20 — Marina: reportar informação incorreta ou suspeita | C21: 5 | D21: =INDEX(Sheet1!$G$6:$G$29,MATCH($B21,Sheet1!$A$6:$A$29,0)) -> 5 | E21: Botão de denúncia com motivo e fila de moderação. Mesmo porte da J10. | F21: =IF(D21>13,"Quebrar (ver item 2)",IF(D21=13,"Manter (no limite)","Manter")) -> Manter
A22: 2 | B22: Jornada 13 — Marina: controlar privacidade das informações profissionais | C22: 5 | D22: =INDEX(Sheet1!$G$6:$G$29,MATCH($B22,Sheet1!$A$6:$A$29,0)) -> 3 | E22: Tela de configuração de quais contatos ficam visíveis; sem regra de negócio complexa. | F22: =IF(D22>13,"Quebrar (ver item 2)",IF(D22=13,"Manter (no limite)","Manter")) -> Manter
A23: 2 | B23: Jornada 11 — Marina: salvar ameaças para investigação posterior | C23: 2 | D23: =INDEX(Sheet1!$G$6:$G$29,MATCH($B23,Sheet1!$A$6:$A$29,0)) -> 2 | E23: História de referência: salvar e listar itens. | F23: =IF(D23>13,"Quebrar (ver item 2)",IF(D23=13,"Manter (no limite)","Manter")) -> Manter
A24: 3 | B24: Jornada 2 — Paulo: acompanhamento e integração da inteligência setorial | C24: 8 | D24: 21 | E24: Área de credenciais, API REST e coleção STIX/TAXII. Duas dessas partes têm, cada uma, o porte da J19. | F24: =IF(D24>13,"Quebrar (ver item 2)",IF(D24=13,"Manter (no limite)","Manter")) -> Quebrar (ver item 2)
A25: 3 | B25: Jornada 18 — Edgar: obter visão executiva das ameaças do setor | C25: 8 | D25: =INDEX(Sheet1!$G$6:$G$29,MATCH($B25,Sheet1!$A$6:$A$29,0)) -> 13 | E25: Maior história mantida: agregações por período, tendências, gráficos e navegação até a publicação. Se a equipe votar acima de 13, separar tendências do painel de ameaças recentes. | F25: =IF(D25>13,"Quebrar (ver item 2)",IF(D25=13,"Manter (no limite)","Manter")) -> Manter (no limite)
A26: 3 | B26: Jornada 19 — Paulo: contribuir com novos IOCs para publicação existente | C26: 5 | D26: =INDEX(Sheet1!$G$6:$G$29,MATCH($B26,Sheet1!$A$6:$A$29,0)) -> 8 | E26: Fluxo de contribuição com revisão e histórico de alterações, que a J17 usa depois. | F26: =IF(D26>13,"Quebrar (ver item 2)",IF(D26=13,"Manter (no limite)","Manter")) -> Manter
A27: 3 | B27: Jornada 5 — Marina: localizar e contatar profissional verificado | C27: 5 | D27: =INDEX(Sheet1!$G$6:$G$29,MATCH($B27,Sheet1!$A$6:$A$29,0)) -> 5 | E27: Diretório com filtro e perfil verificado; a privacidade já vem da J13. | F27: =IF(D27>13,"Quebrar (ver item 2)",IF(D27=13,"Manter (no limite)","Manter")) -> Manter
A28: 3 | B28: Jornada 15 — Paulo: exportar inteligência para ferramentas externas | C28: 8 | D28: =INDEX(Sheet1!$G$6:$G$29,MATCH($B28,Sheet1!$A$6:$A$29,0)) -> 5 | E28: O conversor STIX vem da J2.3; sobra selecionar os dados e gerar o arquivo. | F28: =IF(D28>13,"Quebrar (ver item 2)",IF(D28=13,"Manter (no limite)","Manter")) -> Manter
A29: 3 | B29: Jornada 17 — Marina: acompanhar novas informações de ameaça investigada | C29: 3 | D29: =INDEX(Sheet1!$G$6:$G$29,MATCH($B29,Sheet1!$A$6:$A$29,0)) -> 5 | E29: Precisa registrar o histórico de consultas e destacar o que mudou desde a última visita. | F29: =IF(D29>13,"Quebrar (ver item 2)",IF(D29=13,"Manter (no limite)","Manter")) -> Manter
A31: 2. Quebra das histórias acima de 13 pontos
A32: Épico | B32: Sub-história | C32: Valor de Negócio | D32: Risco | E32: Passos da jornada cobertos | F32: Pontos
A33: J1 (21) | B33: Jornada 1.1 — Enzo: visualizar o feed setorial e os detalhes do ataque | C33: =INDEX(Sheet1!$B$6:$B$29,MATCH($B33,Sheet1!$A$6:$A$29,0)) -> A | D33: =INDEX(Sheet1!$C$6:$C$29,MATCH($B33,Sheet1!$A$6:$A$29,0)) -> B | E33: Passo 3 (feed setorial) e a página de detalhes do ataque, do ofensor e das TTPs citada no passo 5. | F33: =INDEX(Sheet1!$G$6:$G$29,MATCH($B33,Sheet1!$A$6:$A$29,0)) -> 5
A34: J1 (21) | B34: Jornada 1.2 — Enzo: pesquisar IOC com contexto setorial e filtros | C34: =INDEX(Sheet1!$B$6:$B$29,MATCH($B34,Sheet1!$A$6:$A$29,0)) -> A | D34: =INDEX(Sheet1!$C$6:$C$29,MATCH($B34,Sheet1!$A$6:$A$29,0)) -> A | E34: Passos 4 e 5: busca do IOC, ocorrências no setor e filtros por indústria, tipo de IOC e período. | F34: =INDEX(Sheet1!$G$6:$G$29,MATCH($B34,Sheet1!$A$6:$A$29,0)) -> 8
A35: J1 (21) | B35: Jornada 1.3 — Enzo: consultar a reputação do IOC em feeds reputacionais | C35: =INDEX(Sheet1!$B$6:$B$29,MATCH($B35,Sheet1!$A$6:$A$29,0)) -> A | D35: =INDEX(Sheet1!$C$6:$C$29,MATCH($B35,Sheet1!$A$6:$A$29,0)) -> A | E35: Verificação de reputação: integração com feed reputacional externo, com controle do limite de consultas. | F35: =INDEX(Sheet1!$G$6:$G$29,MATCH($B35,Sheet1!$A$6:$A$29,0)) -> 8
B36: Total J1 após a quebra | E36: Passo 1 (cadastro) já está pontuado na J6. Passos 2 e 6 acontecem no SIEM e não geram construção. | F36: =SUM(F33:F35) -> 21
A37: J2 (21) | B37: Jornada 2.1 — Paulo: acessar a área de integrações e gerar credenciais | C37: =INDEX(Sheet1!$B$6:$B$29,MATCH($B37,Sheet1!$A$6:$A$29,0)) -> A | D37: =INDEX(Sheet1!$C$6:$C$29,MATCH($B37,Sheet1!$A$6:$A$29,0)) -> B | E37: Passo 4: área de integrações, documentação e geração ou revogação de credenciais. | F37: =INDEX(Sheet1!$G$6:$G$29,MATCH($B37,Sheet1!$A$6:$A$29,0)) -> 5
A38: J2 (21) | B38: Jornada 2.2 — Paulo: consumir IOCs via API com filtros setoriais | C38: =INDEX(Sheet1!$B$6:$B$29,MATCH($B38,Sheet1!$A$6:$A$29,0)) -> A | D38: =INDEX(Sheet1!$C$6:$C$29,MATCH($B38,Sheet1!$A$6:$A$29,0)) -> A | E38: Passos 5 e 6: API REST com filtros por indústria, tipo e período, respeitando o TLP. | F38: =INDEX(Sheet1!$G$6:$G$29,MATCH($B38,Sheet1!$A$6:$A$29,0)) -> 8
A39: J2 (21) | B39: Jornada 2.3 — Paulo: ingerir inteligência em STIX/TAXII no pipeline interno | C39: =INDEX(Sheet1!$B$6:$B$29,MATCH($B39,Sheet1!$A$6:$A$29,0)) -> A | D39: =INDEX(Sheet1!$C$6:$C$29,MATCH($B39,Sheet1!$A$6:$A$29,0)) -> A | E39: Passo 5: conversão para STIX 2.1 e coleção TAXII para MISP, OpenCTI, SIEM ou SOAR. | F39: =INDEX(Sheet1!$G$6:$G$29,MATCH($B39,Sheet1!$A$6:$A$29,0)) -> 8
B40: Total J2 após a quebra | E40: Passos 1 a 3 reaproveitam feed, filtros e busca do R1. | F40: =SUM(F37:F39) -> 21
A42: 3. Ordem de construção (Scrum)
A43: Ordem | B43: História | C43: Iteração | D43: Pontos | E43: Por que nessa posição | F43: Release
...
